Workbook

Sheet Sheet1
A1: Current known in LingQ | B1: In Skritter? | C1: Move to ignored?
A2: 度 | B2: =VLOOKUP(A2,'Skritter words'!$A$1:$A$4411,1,0) -> 度
A3: 友好 | B3: =VLOOKUP(A3,'Skritter words'!$A$1:$A$4411,1,0) -> 友好
A4: 人头 | B4: =VLOOKUP(A4,'Skritter words'!$A$1:$A$4411,1,0) -> 人头
A5: 就 | B5: =VLOOKUP(A5,'Skritter words'!$A$1:$A$4411,1,0) -> 就
A6: 应该 | B6: =VLOOKUP(A6,'Skritter words'!$A$1:$A$4411,1,0) -> 应该
A7: 怎么样 | B7: =VLOOKUP(A7,'Skritter words'!$A$1:$A$4411,1,0) -> 怎么样
A8: 等等等等 | B8: =VLOOKUP(A8,'Skritter words'!$A$1:$A$4411,1,0) -> #N/A | C8: x
A9: 只是 | B9: =VLOOKUP(A9,'Skritter words'!$A$1:$A$4411,1,0) -> 只是
A10: 见过 | B10: =VLOOKUP(A10,'Skritter words'!$A$1:$A$4411,1,0) -> #N/A | C10: x
A11: 帮助 | B11: =VLOOKUP(A11,'Skritter words'!$A$1:$A$4411,1,0) -> 帮助
A12: 这么 | B12: =VLOOKUP(A12,'Skritter words'!$A$1:$A$4411,1,0) -> 这么
A13: 说 | B13: =VLOOKUP(A13,'Skritter words'!$A$1:$A$4411,1,0) -> 说
A14: 她 | B14: =VLOOKUP(A14,'Skritter words'!$A$1:$A$4411,1,0) -> 她
A15: 丿 | B15: =VLOOKUP(A15,'Skritter words'!$A$1:$A$4411,1,0) -> 丿
A16: 为止 | B16: =VLOOKUP(A16,'Skritter words'!$A$1:$A$4411,1,0) -> 为止
A17: 乃 | B17: =VLOOKUP(A17,'Skritter words'!$A$1:$A$4411,1,0) -> 乃
A18: 之后 | B18: =VLOOKUP(A18,'Skritter words'!$A$1:$A$4411,1,0) -> 之后
A19: 乍 | B19: =VLOOKUP(A19,'Skritter words'!$A$1:$A$4411,1,0) -> 乍
A20: 乙 | B20: =VLOOKUP(A20,'Skritter words'!$A$1:$A$4411,1,0) -> 乙
A21: 九 | B21: =VLOOKUP(A21,'Skritter words'!$A$1:$A$4411,1,0) -> 九
A22: 九点九点 | B22: =VLOOKUP(A22,'Skritter words'!$A$1:$A$4411,1,0) -> #N/A | C22: x
A23: 习 | B23: =VLOOKUP(A23,'Skritter words'!$A$1:$A$4411,1,0) -> 习
A24: 书 | B24: =VLOOKUP(A24,'Skritter words'!$A$1:$A$4411,1,0) -> 书
A25: 亅 | B25: =VLOOKUP(A25,'Skritter words'!$A$1:$A$4411,1,0) -> 亅
A26: 二十 | B26: =VLOOKUP(A26,'Skritter words'!$A$1:$A$4411,1,0) -> 二十
A27: 奶奶 | B27: =VLOOKUP(A27,'Skritter words'!$A$1:$A$4411,1,0) -> 奶奶
A28: 女王 | B28: =VLOOKUP(A28,'Skritter words'!$A$1:$A$4411,1,0) -> 女王
A29: 尢 | B29: =VLOOKUP(A29,'Skritter words'!$A$1:$A$4411,1,0) -> 尢
A30: 好像 | B30: =VLOOKUP(A30,'Skritter words'!$A$1:$A$4411,1,0) -> 好像
A31: 尤 | B31: =VLOOKUP(A31,'Skritter words'!$A$1:$A$4411,1,0) -> 尤
A32: 尸 | B32: =VLOOKUP(A32,'Skritter words'!$A$1:$A$4411,1,0) -> 尸
A33: 尼 | B33: =VLOOKUP(A33,'Skritter words'!$A$1:$A$4411,1,0) -> 尼
A34: 尼克 | B34: =VLOOKUP(A34,'Skritter words'!$A$1:$A$4411,1,0) -> 尼克
A35: 奶 | B35: =VLOOKUP(A35,'Skritter words'!$A$1:$A$4411,1,0) -> 奶
A36: 好不 | B36: =VLOOKUP(A36,'Skritter words'!$A$1:$A$4411,1,0) -> #N/A | C36: x
A37: 好不好 | B37: =VLOOKUP(A37,'Skritter words'!$A$1:$A$4411,1,0) -> 好不好
A38: 好人 | B38: =VLOOKUP(A38,'Skritter words'!$A$1:$A$4411,1,0) -> 好人
A39: 好吃 | B39: =VLOOKUP(A39,'Skritter words'!$A$1:$A$4411,1,0) -> 好吃
A40: 好吃不好吃 | B40: =VLOOKUP(A40,'Skritter words'!$A$1:$A$4411,1,0) -> 好吃不好吃
...

Sheet Skritter words
A1: 势
A2: 组织
A3: 不得不
A4: 纹
A5: 民众
A6: 降世神通
A7: 桃子
A8: 部长
A9: 弊
A10: 排队
A11: 眠
A12: 军团
... A4411: 石
